Workbook
Name AI_and_data_science: Sheet5!$AB$2:$AB$5
Name BNS4_AIS2_S1: Sheet5!$C$2:$C$25
Name BNS4_AIS4_S1: Sheet5!$C$26:$C$39
Name BNS4_AIS5_S1: Sheet5!$C$40:$C$63
Name BNS4_SWD2_S1: Sheet5!$C$64:$C$78
Name CAI4_AIS2_G1: Sheet5!$C$79:$C$103
Name CAI4_AIS2_G2: Sheet5!$C$104:$C$126
Name CAI4_AIS2_S1: Sheet5!$C$127:$C$151
Name CAI4_AIS3_G1: Sheet5!$C$152:$C$168
Name CAI4_AIS3_S1: Sheet5!$C$169:$C$186
Name CAI4_AIS4_G2: Sheet5!$C$187:$C$204
Name CAI4_AIS4_S1: Sheet5!$C$205:$C$227
Name CAI4_AIS5_G1: Sheet5!$C$228:$C$249
Name CAI4_SWD6_G2: Sheet5!$C$250:$C$271
Name CAI4_SWD6_S1: Sheet5!$C$272:$C$296
Name CAI4_SWD6_S2: Sheet5!$C$297:$C$318
Name CAI4_SWD6_S3: Sheet5!$C$319:$C$340
Name Cyber_Security_Incident_Response_Analyst: Sheet5!$W$2:$W$5
Name Data_Scientist: Sheet5!$W$6:$W$12
Name Generative_AI_Professional: Sheet5!$W$13:$W$19
Name GIZ4_AIS2_S1: Sheet5!$C$341:$C$365
Name GIZ4_AIS2_S2: Sheet5!$C$366:$C$389
Name GIZ4_AIS2_S6: Sheet5!$C$390:$C$411
Name GIZ4_AIS3_G1: Sheet5!$C$412:$C$427
Name GIZ4_AIS3_S1: Sheet5!$C$428:$C$445
Name GIZ4_AIS4_G1: Sheet5!$C$446:$C$465
Name GIZ4_AIS4_S1: Sheet5!$C$466:$C$480
Name GIZ4_SWD6_G1: Sheet5!$C$481:$C$505
Name GIZ4_SWD6_S1: Sheet5!$C$506:$C$520
Name GIZ4_SWD6_S2: Sheet5!$C$521:$C$540
Name InfraStructure_and_Security: Sheet5!$AB$6
Name Microsoft_Data_Engineer: Sheet5!$W$20:$W$27
Name Microsoft_Machine_Learning_Engineer: Sheet5!$W$28:$W$36
Name MNF4_ISS2_S1: Sheet5!$C$541:$C$566
Name MNF4_SWD6_S1: Sheet5!$C$567:$C$587
Name ONL4_AIS2_G3: Sheet5!$C$588:$C$604
Name ONL4_AIS2_S2: Sheet5!$C$605:$C$634
Name ONL4_AIS3_G1: Sheet5!$C$635:$C$650
Name ONL4_AIS3_S2: Sheet5!$C$651:$C$679
Name ONL4_AIS3_S3: Sheet5!$C$680:$C$708
Name ONL4_AIS4_S2: Sheet5!$C$709:$C$731
Name ONL4_AIS4_S4: Sheet5!$C$732:$C$761
Name ONL4_AIS5_G1: Sheet5!$C$762:$C$790
Name ONL4_AIS5_G5: Sheet5!$C$791:$C$816
Name ONL4_AIS5_S3: Sheet5!$C$817:$C$846
Name ONL4_AIS5_S6: Sheet5!$C$847:$C$875
Name ONL4_AIS5_S7: Sheet5!$C$876:$C$901
Name ONL4_AIS5_S8: Sheet5!$C$902:$C$930
Name ONL4_ISS2_G1: Sheet5!$C$931:$C$946
Name ONL4_ISS2_S1: Sheet5!$C$947:$C$978
Name ONL4_ISS2_S2: Sheet5!$C$979:$C$1011
Name ONL4_SWD2_G3: Sheet5!$C$1012:$C$1031
Name ONL4_SWD6_G1: Sheet5!$C$1032:$C$1057
Name ONL4_SWD6_G3: Sheet5!$C$1058:$C$1076
Name ONL4_SWD6_S1: Sheet5!$C$1077:$C$1106
Name ONL4_SWD6_S3: Sheet5!$C$1107:$C$1132
Name ONL4_SWD6_S4: Sheet5!$C$1133:$C$1161
Name React_Frontend_Web_Developer: Sheet5!$W$37:$W$38
Name Software_Development: Sheet5!$AB$7:$AB$8
Name Software_Tester: Sheet5!$W$39:$W$51

Sheet Instructions
C7: Instructions:
C8: The grading sheet should be filled for every student as per the rubric below.
C11: Grade | D11: Unacceptable (0) | E11: Acceptable (5)
C12: Group formation (5/100) | D12: Group members are not identified and notified to the instructor in a timely manner. | E12: Group members are identified and notified to the instructor in a timely manner.
C15: Grade | D15: Unacceptable (from 0 to 1) | E15: Acceptable (from 2 to 3) | F15: Good (from 4 to 5)
C16: Task Division (5/100) | D16: The work was not clearly divided among the group members and reported to the coach in a timely manner. | E16: The work was divided into sub-tasks, distributed among the group members and reported to the coach in a timely manner. | F16: The work was divided into adequate sub-tasks, distributed among the group members and reported to the coach in a timely manner.
C19: Grade | D19: Unacceptable (from 0 to 2) | E19: Acceptable (from 3 to 5) | F19: Good (from 6 to 8) | G19: Superior (from 9 to 10)
C20: Research question, Problem definition (10/100) | D20: Failed to communicate the question and/or its significance. | E20: Adequately communicated the question and/or its significance. | F20: Clearly communicated the question to be addressed and/or its significance. | G20: Clearly and fully communicated the question to be addressed and its significance.
C23: Grade | D23: Unacceptable (from 0 to 4) | E23: Acceptable (from 5 to 9) | F23: Good (from 9 to 14) | G23: Superior (from 15 to 20)
C24: Methods, Algorithms, Teqniques (20/100) | D24: The student has failed to communicate the methodology to be employed and/or its appropriateness to the question | E24: The student has adequately communicated the methodology to be employed and/or its appropriateness to the question | F24: The student has clearly communicated the methodology to be employed and/or its appropriateness to the question | G24: The student has clearly and fully communicated the methodology to be employed and its appropriateness to the question
C25: ٌResults / Outcomes (20/100) | D25: Student has failed to define the hypothesis to be investigated, and/or the potential outcomes, and/or how they will be distinguished | E25: Student has adequately defined the hypothesis to be investigated, and/or the potential outcomes, and/or how they will be distinguished | F25: Student has clearly defined the hypothesis to be investigated, the potential outcomes, and/or how they will be distinguished | G25: Student has clearly and fully defined the hypothesis to be investigated, the potential outcomes, and how they will be distinguished
C26: Content and organization , (20/100) | D26: The presentation fails to convey the problem, the methodology, data analysis, interpretation and results | E26: The presentation adequately conveys the problem, the methodology, data analysis, interpretation and results | F26: The presentation clearly conveys the problem, the methodology, data analysis, interpretation and results | G26: The presentation clearly and fully communicates the problem, the methodology, data analysis, interpretation and results in a professional manner
C27: Q&A | D27: Student’s responses fails to demonstrate an understanding and/or depth of the problem | E27: Student’s responses demonstrate an incomplete understanding and/or depth of the problem | F27: Student’s responses demonstrate complete understanding and depth of the problem | G27: Student’s responses clearly demonstrate complete understanding and depth of the problem beyond the presentation

Sheet Grading
B8: # | C8: Training Provider | D8: Track | E8: Profile | F8: Group ID | G8: Team Group | H8: Student ID | I8: Students Name | J8: Students Email | K8: Mobile Number | L8: Project name | M8: project GitHub Link | N8: Idea & Objectives (10/100) | O8: System Analysis & Requirements / Design (15/100) | P8: Algorithms / Methods / techniques(20/100) | Q8: Implementation & Coding / Results (20/100) | R8: Testing & Documentation (10/100) | S8: Innovation & Added Value (10/100) | T8: Presentation & Demo(10/100) | U8: Final Submission & Delivery (5/100) | V8: Total (100/100)
B9: 1 | C9: AMT | H9: =_xlfn.XLOOKUP(I9,Sheet5!C:C,Sheet5!A:A,0) -> 0 | J9: =_xlfn.XLOOKUP(I9,Sheet5!C:C,Sheet5!B:B,0,0) -> 0 | K9: =_xlfn.XLOOKUP(I9,Sheet5!C:C,Sheet5!D:D,0,0) -> 0 | V9: =SUM(N9:U9) -> 0
B10: 2 | C10: AMT | H10: =_xlfn.XLOOKUP(I10,Sheet5!C:C,Sheet5!A:A,0) -> 0 | J10: =_xlfn.XLOOKUP(I10,Sheet5!C:C,Sheet5!B:B,0,0) -> 0 | K10: =_xlfn.XLOOKUP(I10,Sheet5!C:C,Sheet5!D:D,0,0) -> 0 | V10: =SUM(N10:U10) -> 0
B11: 3 | C11: AMT | H11: =_xlfn.XLOOKUP(I11,Sheet5!C:C,Sheet5!A:A,0) -> 0 | J11: =_xlfn.XLOOKUP(I11,Sheet5!C:C,Sheet5!B:B,0,0) -> 0 | K11: =_xlfn.XLOOKUP(I11,Sheet5!C:C,Sheet5!D:D,0,0) -> 0 | V11: =SUM(N11:U11) -> 0
B12: 4 | C12: AMT | H12: =_xlfn.XLOOKUP(I12,Sheet5!C:C,Sheet5!A:A,0) -> 0 | J12: =_xlfn.XLOOKUP(I12,Sheet5!C:C,Sheet5!B:B,0,0) -> 0 | K12: =_xlfn.XLOOKUP(I12,Sheet5!C:C,Sheet5!D:D,0,0) -> 0 | V12: =SUM(N12:U12) -> 0
B13: 5 | C13: AMT | H13: =_xlfn.XLOOKUP(I13,Sheet5!C:C,Sheet5!A:A,0) -> 0 | J13: =_xlfn.XLOOKUP(I13,Sheet5!C:C,Sheet5!B:B,0,0) -> 0 | K13: =_xlfn.XLOOKUP(I13,Sheet5!C:C,Sheet5!D:D,0,0) -> 0 | V13: =SUM(N13:U13) -> 0
B14: 6 | C14: AMT | H14: =_xlfn.XLOOKUP(I14,Sheet5!C:C,Sheet5!A:A,0) -> 0 | J14: =_xlfn.XLOOKUP(I14,Sheet5!C:C,Sheet5!B:B,0,0) -> 0 | K14: =_xlfn.XLOOKUP(I14,Sheet5!C:C,Sheet5!D:D,0,0) -> 0 | V14: =SUM(N14:U14) -> 0
B15: 7 | C15: AMT | H15: =_xlfn.XLOOKUP(I15,Sheet5!C:C,Sheet5!A:A,0) -> 0 | J15: =_xlfn.XLOOKUP(I15,Sheet5!C:C,Sheet5!B:B,0,0) -> 0 | K15: =_xlfn.XLOOKUP(I15,Sheet5!C:C,Sheet5!D:D,0,0) -> 0 | V15: =SUM(N15:U15) -> 0
B16: 8 | C16: AMT | H16: =_xlfn.XLOOKUP(I16,Sheet5!C:C,Sheet5!A:A,0) -> 0 | J16: =_xlfn.XLOOKUP(I16,Sheet5!C:C,Sheet5!B:B,0,0) -> 0 | K16: =_xlfn.XLOOKUP(I16,Sheet5!C:C,Sheet5!D:D,0,0) -> 0 | V16: =SUM(N16:U16) -> 0
B17: 9 | C17: AMT | H17: =_xlfn.XLOOKUP(I17,Sheet5!C:C,Sheet5!A:A,0) -> 0 | J17: =_xlfn.XLOOKUP(I17,Sheet5!C:C,Sheet5!B:B,0,0) -> 0 | K17: =_xlfn.XLOOKUP(I17,Sheet5!C:C,Sheet5!D:D,0,0) -> 0 | V17: =SUM(N17:U17) -> 0
B18: 10 | C18: AMT | H18: =_xlfn.XLOOKUP(I18,Sheet5!C:C,Sheet5!A:A,0) -> 0 | J18: =_xlfn.XLOOKUP(I18,Sheet5!C:C,Sheet5!B:B,0,0) -> 0 | K18: =_xlfn.XLOOKUP(I18,Sheet5!C:C,Sheet5!D:D,0,0) -> 0 | V18: =SUM(N18:U18) -> 0
B19: 11 | C19: AMT | H19: =_xlfn.XLOOKUP(I19,Sheet5!C:C,Sheet5!A:A,0) -> 0 | J19: =_xlfn.XLOOKUP(I19,Sheet5!C:C,Sheet5!B:B,0,0) -> 0 | K19: =_xlfn.XLOOKUP(I19,Sheet5!C:C,Sheet5!D:D,0,0) -> 0 | V19: =SUM(N19:U19) -> 0
B20: 12 | C20: AMT | H20: =_xlfn.XLOOKUP(I20,Sheet5!C:C,Sheet5!A:A,0) -> 0 | J20: =_xlfn.XLOOKUP(I20,Sheet5!C:C,Sheet5!B:B,0,0) -> 0 | K20: =_xlfn.XLOOKUP(I20,Sheet5!C:C,Sheet5!D:D,0,0) -> 0 | V20: =SUM(N20:U20) -> 0
... B43: 35 | C43: AMT | H43: =_xlfn.XLOOKUP(I43,Sheet5!C:C,Sheet5!A:A,0) -> 0 | J43: =_xlfn.XLOOKUP(I43,Sheet5!C:C,Sheet5!B:B,0,0) -> 0 | K43: =_xlfn.XLOOKUP(I43,Sheet5!C:C,Sheet5!D:D,0,0) -> 0 | V43: =SUM(N43:U43) -> 0

Sheet Sheet5
A1: StudentId | B1: email | C1: nameEn | D1: phone | E1: jobProfile1 | F1: specialty1 | H1: tp | I1: Updated Group code | J1: Status | K1: Note | L1: Status2 | M1: Join date | Q1: Track | R1: profile | S1: Final Round Code | V1: profile | W1: Final Round Code | AA1: Track | AB1: profile
A2: 21120375 | B2: farngec@gmail.com | C2: Ahmed Saber Abdelwahab | D2: 1142619610 | E2: Microsoft Machine Learning Engineer | F2: AI & Data Science | H2: AMT | I2: BNS4_AIS2_S1 | J2: تم اضافته | L2: Round 4 | M2: 45989 | Q2: Software_Development | R2: Software_Tester | S2: ONL4_SWD6_S4 | V2: Cyber_Security_Incident_Response_Analyst | W2: MNF4_ISS2_S1 | AA2: AI_and_data_science | AB2: Microsoft_Machine_Learning_Engineer
A3: 21084315 | B3: sleemhashem620@gmail.com | C3: Sleem Hashem Abdelwahab | D3: 1154825799 | E3: Microsoft Machine Learning Engineer | F3: AI & Data Science | H3: AMT | I3: BNS4_AIS2_S1 | J3: تم اضافته | L3: Round 4 | M3: 45989 | Q3: Software_Development | R3: Software_Tester | S3: ONL4_SWD6_S3 | V3: Cyber_Security_Incident_Response_Analyst | W3: ONL4_ISS2_S1 | AA3: AI_and_data_science | AB3: Generative_AI_Professional
A4: 21124154 | B4: moyehia231@gmail.com | C4: Mohamed Yehia Mohamed | D4: 1120155119 | E4: Microsoft Machine Learning Engineer | F4: AI & Data Science | H4: AMT | I4: BNS4_AIS2_S1 | J4: تم اضافته | L4: Round 4 | M4: 45989 | Q4: InfraStructure_and_Security | R4: Cyber_Security_Incident_Response_Analyst | S4: MNF4_ISS2_S1 | V4: Cyber_Security_Incident_Response_Analyst | W4: ONL4_ISS2_G1 | AA4: AI_and_data_science | AB4: Data_Scientist
A5: 21056367 | B5: mariomagdy12yahoo@gmail.com | C5: Mario Magdy Aziz | D5: 1282143645 | E5: Microsoft Machine Learning Engineer | F5: AI & Data Science | H5: AMT | I5: BNS4_AIS2_S1 | J5: تم اضافته | L5: Achiever | M5: 45989 | Q5: AI_and_data_Science | R5: Microsoft_Machine_Learning_Engineer | S5: CAI4_AIS2_G2 | V5: Cyber_Security_Incident_Response_Analyst | W5: ONL4_ISS2_S2 | AA5: AI_and_data_science | AB5: Microsoft_Data_Engineer
A6: 21082885 | B6: gaafergoudacs50@gmail.com | C6: Gaafer Mohsen Mahmoud | D6: 1020396619 | E6: Microsoft Machine Learning Engineer | F6: AI & Data Science | H6: AMT | I6: BNS4_AIS2_S1 | J6: تم اضافته | L6: Achiever | M6: 45989 | Q6: AI_and_data_Science | R6: Microsoft_Machine_Learning_Engineer | S6: ONL4_AIS2_G3 | V6: Data_Scientist | W6: GIZ4_AIS4_G1 | AA6: InfraStructure_and_Security | AB6: Cyber_Security_Incident_Response_Analyst
A7: 21084087 | B7: nosibahamdy1@gmail.com | C7: Nosiba Hamdy Mohammed | D7: 1556881309 | E7: Microsoft Machine Learning Engineer | F7: AI & Data Science | H7: AMT | I7: BNS4_AIS2_S1 | J7: تم اضافته | L7: Achiever | M7: 45989 | Q7: AI_and_data_Science | R7: Generative_AI_Professional | S7: ONL4_AIS3_G1 | V7: Data_Scientist | W7: BNS4_AIS4_S1 | AA7: Software_Development | AB7: Software_Tester
A8: 21123626 | B8: yousef.alaa0359@nub.edu.eg | C8: Yousef Alaa Fathy | D8: 1020821485 | E8: Microsoft Machine Learning Engineer | F8: AI & Data Science | H8: AMT | I8: BNS4_AIS2_S1 | J8: تم اضافته | L8: Round 4 | M8: 45989 | Q8: AI_and_data_Science | R8: Data_Scientist | S8: GIZ4_AIS4_G1 | V8: Data_Scientist | W8: ONL4_AIS4_S4 | AA8: Software_Development | AB8: React_Frontend_Web_Developer
A9: 21096921 | B9: mohamedaqyla@gmail.com | C9: Mohamed Aqela Fayed | D9: 1152382741 | E9: Microsoft Machine Learning Engineer | H9: AMT | I9: BNS4_AIS2_S1 | J9: تم اضافته | L9: Achiever | M9: 45989 | Q9: Software_Development | R9: Software_Tester | S9: ONL4_SWD6_S1 | V9: Data_Scientist | W9: ONL4_AIS4_S2
A10: 21012466 | B10: abdullahshahd335@gmail.com | C10: Shahd Abdullah Glal | D10: 1146347996 | E10: Microsoft Machine Learning Engineer | F10: AI & Data Science | H10: AMT | I10: BNS4_AIS2_S1 | J10: تم اضافته | L10: Round 4 | M10: 45989 | Q10: Software_Development | R10: Software_Tester | S10: ONL4_SWD6_G3 | V10: Data_Scientist | W10: GIZ4_AIS4_S1
A11: 21119150 | B11: alym9517@gmail.com | C11: Ali Mohamed Ali | D11: 1098479392 | E11: Microsoft Machine Learning Engineer | F11: AI & Data Science | H11: AMT | I11: BNS4_AIS2_S1 | J11: تم اضافته | L11: Round 4 | M11: 45989 | Q11: Software_Development | R11: React_Frontend_Web_Developer | S11: BNS4_SWD2_S1 | V11: Data_Scientist | W11: CAI4_AIS4_S1
A12: 21108912 | B12: a.gamal0947@nub.edu.eg | C12: Aya Gamal Abdulbaset | D12: 1005062890 | E12: Microsoft Machine Learning Engineer | F12: AI & Data Science | H12: AMT | I12: BNS4_AIS2_S1 | J12: تم اضافته | L12: Round 4 | M12: 45989 | Q12: AI_and_data_Science | R12: Microsoft_Machine_Learning_Engineer | S12: BNS4_AIS2_S1 | V12: Data_Scientist | W12: CAI4_AIS4_G2
A13: 21132190 | B13: alsarraaadel@gmail.com | C13: Alsaraa Adel Abdullah | D13: 1123047321 | E13: Microsoft Machine Learning Engineer | F13: AI & Data Science | H13: AMT | I13: BNS4_AIS2_S1 | J13: تم اضافته | L13: Round 4 | M13: 45989 | Q13: AI_and_data_Science | R13: Microsoft_Data_Engineer | S13: CAI4_AIS5_G1 | V13: Generative_AI_Professional | W13: ONL4_AIS3_G1
A14: 21128007 | B14: h.ayman7119@nub.edu.eg | C14: Hussein Ayman Hussein | D14: 1156047992 | E14: Microsoft Machine Learning Engineer | F14: AI & Data Science | H14: AMT | I14: BNS4_AIS2_S1 | J14: تم اضافته | L14: Round 4 | M14: 45989 | Q14: AI_and_data_Science | R14: Microsoft_Data_Engineer | S14: BNS4_AIS5_S1 | V14: Generative_AI_Professional | W14: CAI4_AIS3_S1
A15: 21073333 | B15: omniaaragab.12@gmail.com | C15: Omnia Ragab Kamal | D15: 1153822591 | E15: Microsoft Machine Learning Engineer | F15: AI & Data Science | H15: AMT | I15: BNS4_AIS2_S1 | J15: تم اضافته | L15: Achiever | M15: 45989 | Q15: AI_and_data_Science | R15: Data_Scientist | S15: BNS4_AIS4_S1 | V15: Generative_AI_Professional | W15: CAI4_AIS3_G1
A16: 21132784 | B16: kerojo754@gmail.com | C16: George Hany Maher | D16: 1279139625 | E16: Microsoft Machine Learning Engineer | F16: AI & Data Science | H16: AMT | I16: BNS4_AIS2_S1 | J16: تم اضافته | L16: Round 4 | M16: 45989 | Q16: Software_Development | R16: Software_Tester | S16: ONL4_SWD6_G1 | V16: Generative_AI_Professional | W16: GIZ4_AIS3_G1
A17: 21040063 | B17: pasharmohamed8@gmail.com | C17: Bashar Mohamed Sayed | D17: 1144656494 | E17: Microsoft Machine Learning Engineer | F17: AI & Data Science | H17: AMT | I17: BNS4_AIS2_S1 | J17: تم اضافته | L17: Round 4 | M17: 45989 | Q17: Software_Development | R17: Software_Tester | S17: MNF4_SWD6_S1 | V17: Generative_AI_Professional | W17: GIZ4_AIS3_S1
A18: 21056410 | B18: ahmedkhgg9@gmail.com | C18: Ahmed Khaled Mohamed | D18: 1030668462 | E18: Microsoft Machine Learning Engineer | F18: AI & Data Science | H18: AMT | I18: BNS4_AIS2_S1 | J18: تم اضافته | L18: Round 4 | M18: 45989 | Q18: Software_Development | R18: React_Frontend_Web_Developer | S18: ONL4_SWD2_G3 | V18: Generative_AI_Professional | W18: ONL4_AIS3_S3
A19: 21048638 | B19: abkarinoalaa@gmail.com | C19: Abdelazem Alaa Eldin Abdelazem | D19: 1004747480 | E19: Microsoft Machine Learning Engineer | F19: AI & Data Science | H19: AMT | I19: BNS4_AIS2_S1 | J19: تم اضافته | L19: Round 4 | M19: 45989 | Q19: InfraStructure_and_Security | R19: Cyber_Security_Incident_Response_Analyst | S19: ONL4_ISS2_S1 | V19: Generative_AI_Professional | W19: ONL4_AIS3_S2
A20: 21133525 | B20: farahahmed7710@gmail.com | C20: Farah Ahmed Farouk | D20: 1096335677 | E20: Microsoft Machine Learning Engineer | F20: AI & Data Science | H20: AMT | I20: BNS4_AIS2_S1 | J20: تم اضافته | L20: Round 4 | M20: 45989 | Q20: InfraStructure_and_Security | R20: Cyber_Security_Incident_Response_Analyst | S20: ONL4_ISS2_G1 | V20: Microsoft_Data_Engineer | W20: CAI4_AIS5_G1
A21: 21123786 | B21: shahdsayedslym939@gmail.com | C21: Shahd Sayed Raai | D21: 1104630172 | E21: Microsoft Machine Learning Engineer | F21: AI & Data Science | H21: AMT | I21: BNS4_AIS2_S1 | J21: تم اضافته | L21: Round 4 | M21: 45989 | Q21: InfraStructure_and_Security | R21: Cyber_Security_Incident_Response_Analyst | S21: ONL4_ISS2_S2 | V21: Microsoft_Data_Engineer | W21: BNS4_AIS5_S1
... A51: 21127062 | B51: rohandaelshrif1@gmail.com | C51: Rohanda Wael Mohamed | D51: 1117772085 | E51: Microsoft Data Engineer | F51: AI & Data Science | H51: AMT | I51: BNS4_AIS5_S1 | J51: تم اضافته | L51: Round 4 | M51: 45989 | Q51: AI_and_data_Science | R51: Microsoft_Data_Engineer | S51: ONL4_AIS5_S7 | V51: Software_Tester | W51: CAI4_SWD6_G2
A52: 21086046 | B52: mohammedyousef998877@gmail.com | C52: Mohamed Youseef Gomaa | D52: 1159341274 | E52: Microsoft Data Engineer | F52: AI & Data Science | H52: AMT | I52: BNS4_AIS5_S1 | J52: تم اضافته | L52: Round 4 | M52: 45989
A53: 21019611 | B53: esraa.osama1050@nub.edu.eg | C53: Esraa Osama Abd El Rahman | D53: 1027668514 | E53: Microsoft Data Engineer | F53: AI & Data Science | H53: AMT | I53: BNS4_AIS5_S1 | J53: تم اضافته | L53: Round 4 | M53: 45989
A54: 21053965 | B54: ayatfakhary4@gmail.com | C54: Ayat Mohamed Fakhry | D54: 1095103433 | E54: Microsoft Data Engineer | F54: AI & Data Science | H54: AMT | I54: BNS4_AIS5_S1 | J54: تم اضافته | L54: Achiever | M54: 45989
A55: 21004356 | B55: abdulrahm3n1511@gmail.com | C55: Abdulrahman Yasser Mahmoud | D55: 1113079942 | E55: Microsoft Data Engineer | F55: AI & Data Science | H55: AMT | I55: BNS4_AIS5_S1 | J55: تم اضافته | L55: Round 4 | M55: 45989
A56: 21133903 | B56: ziyad.ahmed.hashem@gmail.com | C56: Zyad Ahmed Hashem | D56: 1212727518 | E56: Microsoft Data Engineer | F56: AI & Data Science | H56: AMT | I56: BNS4_AIS5_S1 | J56: تم اضافته | L56: Round 4 | M56: 45989
A57: 21122968 | B57: yoa4068@gmail.com | C57: Youssef Ashraf Abdelhamed | D57: 1050971294 | E57: Microsoft Data Engineer | F57: AI & Data Science | H57: AMT | I57: BNS4_AIS5_S1 | J57: تم اضافته | L57: Round 4 | M57: 45989
A58: 21137473 | B58: elamearyy@gmail.com | C58: Ahmed Mostafa Mohamed | D58: 1126823471 | E58: Microsoft Data Engineer | F58: AI & Data Science | H58: AMT | I58: BNS4_AIS5_S1 | J58: تم اضافته | L58: Round 4 | M58: 45989
A59: 21069372 | B59: genius.ahmed.samy12373@gmail.com | C59: Ahmed Samy Hassan | D59: 1159695698 | E59: Microsoft Data Engineer | F59: AI & Data Science | H59: AMT | I59: BNS4_AIS5_S1 | J59: تم اضافته | L59: Round 4 | M59: 45989
A60: 21131191 | B60: jehadamjad501@gmail.com | C60: Jehad Amjad Mahmoud | D60: 1030563272 | E60: Microsoft Data Engineer | F60: AI & Data Science | H60: AMT | I60: BNS4_AIS5_S1 | J60: تم اضافته | L60: Round 4 | M60: 45989
A61: 21125845 | B61: sh1512799@gmail.com | C61: Sara Mohamed Hussein | D61: 1092060547 | E61: Microsoft Data Engineer | F61: AI & Data Science | H61: AMT | I61: BNS4_AIS5_S1 | J61: تم اضافته | L61: Round 4 | M61: 45989
A62: 21134689 | B62: nadaabdelshafy22@gmail.com | C62: Nada Mohammed Abdelshafy | D62: 1103155615 | E62: Microsoft Data Engineer | F62: AI & Data Science | H62: AMT | I62: BNS4_AIS5_S1 | J62: تم اضافته | L62: Round 4 | M62: 45989
A63: 21052884 | B63: 7amo.s7alaby@gmail.com | C63: Mohamed Hossam Amin | D63: 1064726379 | E63: Microsoft Data Engineer | F63: AI & Data Science | H63: AMT | I63: BNS4_AIS5_S1 | J63: تم اضافته | L63: Round 4 | M63: 45989
... A162: 21086353 | B162: rawanrezk04@gmail.com | C162: Rawan Ahmed Ibrahim | D162: 1140233395 | E162: Generative AI Professional | F162: AI & Data Science | H162: AMT | I162: CAI4_AIS3_G1 | J162: تم اضافته | L162: Achiever | M162: 45989
A163: 21067217 | B163: manarawafa@gmail.com | C163: Manar Mahmoud Aboelwafa | D163: 1558916001 | E163: Generative AI Professional | F163: AI & Data Science | H163: AMT | I163: CAI4_AIS3_G1 | J163: تم اضافته | K163: الطالبه كانت مقدمه طلب اعتذار وتراجعت عنه | L163: Achiever | M163: 45989
A164: 21135950 | B164: mennaossama00@gmail.com | C164: Mennatallah Osama Mohamed Hassan | D164: 1156993404 | E164: Generative AI Professional | F164: AI & Data Science | H164: AMT | I164: CAI4_AIS3_G1 | J164: تم اضافته | L164: Round 4 | M164: 45989
A165: 21108152 | B165: wael.elmalky2025@gmail.com | C165: Wael Elsayed Elsayed | D165: 1065548278 | E165: Generative AI Professional | F165: AI & Data Science | H165: AMT | I165: CAI4_AIS3_G1 | J165: تم اضافته | L165: Round 4 | M165: 45989
A166: 21108732 | B166: abdalla_shaker@hotmail.com | C166: Abdallah Gamal Muhammed | D166: 1099261980 | E166: Generative AI Professional | F166: AI & Data Science | H166: AMT | I166: CAI4_AIS3_G1 | J166: تم اضافته | L166: Round 4 | M166: 45989
A167: 21024897 | B167: mariam.essam2910@gmail.com | C167: Mariam Essam Abdelaziz | D167: 1110344311 | E167: Generative AI Professional | F167: AI & Data Science | H167: AMT | I167: CAI4_AIS3_G1 | J167: تم اضافته | L167: Round 4 | M167: 45990
...

Sheet Sheet3
C2: Row Labels
A3: Row Labels | C3: Cyber Security Incident Response Analyst
A4: AI & data Science | C4: Data Scientist
A5: InfraStructure & Security | C5: Generative AI Professional
A6: Software Development | C6: Microsoft Data Engineer
A7: Grand Total | C7: Microsoft Machine Learning Engineer
C8: React Frontend Web Developer
C9: Software Tester
C10: Grand Total
A12: Row Labels | B12: Count of Final Round Code
A13: BNS4_AIS2_S1 | B13: 1
A14: BNS4_AIS4_S1 | B14: 1
A15: BNS4_AIS5_S1 | B15: 1
A16: BNS4_SWD2_S1 | B16: 1
A17: CAI4_AIS2_G1 | B17: 1
A18: CAI4_AIS2_G2 | B18: 1
A19: CAI4_AIS2_S1 | B19: 1
A20: CAI4_AIS3_G1 | B20: 1
A21: CAI4_AIS3_S1 | B21: 1
A22: CAI4_AIS4_G2 | B22: 1
A23: CAI4_AIS4_S1 | B23: 1
A24: CAI4_AIS5_G1 | B24: 1
... A63: Grand Total | B63: 50

Sheet Sheet2
A1: Gov | B1: Training provider | C1: Track | D1: profile | E1: Final Round Code | F1: no. of students | G1: Instructor Name | H1: Instructor Number | I1: Instructor Contact Email | J1: Instructor national ID | K1: Day1 | L1: Time1 | M1: Delivery1 | N1: Day2 | O1: Time2 | P1: Delivery2 | Q1: Day3 | R1: Time3 | S1: Delivery3 | T1: softskills company | U1: Session Platform | V1: Center Name | W1: Center Address | X1: GPS location String | Y1: Type of Group | Z1: Student & graduated | AA1: Current count (Applicant Db) | AB1: Max Capacity | AC1: channel link | AD1: Start date
A2: ONL | B2: AMT | C2: Software Development | D2: Software Tester | E2: ONL4_SWD6_S4 | F2: 29 | G2: Ahmed Hamdy | H2: 01154222743-01031367367 | I2: ahmed.hamdy@amit-learning.com | J2: 30011140105356 | K2: Friday | L2: 1:00 PM - 4:00 PM | M2: ONL | N2: Monday | O2: 7:00 PM - 10:00 PM | P2: ONL | Q2: Saturday | R2: 7:00 PM - 10:00 PM | S2: ONL | T2: Nova | V2: Online | W2: Online | X2: Online | Y2: ONL | Z2: Student | AA2: 29 | AB2: 30 | AD2: 46354
A3: ONL | B3: AMT | C3: Software Development | D3: Software Tester | E3: ONL4_SWD6_S3 | F3: 26 | G3: Amira Hussein | H3: 1003507245 | I3: amira.hussein@amit-learning.com | J3: 29606152502464 | K3: Friday | L3: 1:00 PM - 4:00 PM | M3: ONL | N3: Monday | O3: 7:00 PM - 10:00 PM | P3: ONL | Q3: Saturday | R3: 7:00 PM - 10:00 PM | S3: ONL | T3: Nova | V3: Online | W3: Online | X3: Online | Y3: ONL | Z3: Student | AA3: 29 | AB3: 30 | AD3: 46354
A4: MNF | B4: AMT | C4: InfraStructure & Security | D4: Cyber Security Incident Response Analyst | E4: MNF4_ISS2_S1 | F4: 26 | G4: Mostafa Abdelmonem | H4: 1555734733 | J4: 29907300000000 | K4: Saturday | L4: 1:00 AM - 4:00 PM | M4: PHY | N4: Monday | O4: 7:00 PM - 10:00 PM | P4: ONL | Q4: Wednesday | R4: 7:00 PM - 10:00 PM | S4: ONL | T4: Nova | U4: even | V4: كلية الحاسبات و المعلومات جامعة المنوفية | W4: الدور الرابع علوى | X4: https://maps.app.goo.gl/Xxd9ZjGnW4vEsJpb8 | Y4: even | Z4: Student | AA4: 26 | AB4: 25 | AD4: 46355
A5: CAI | B5: AMT | C5: AI & data Science | D5: Microsoft Machine Learning Engineer | E5: CAI4_AIS2_G2 | F5: 23 | G5: Omnia Ahmed | H5: 1155211664 | I5: Omnia.Ahmed@amit-learning.com | J5: 29507041400168 | K5: Friday | L5: 4:00 PM - 7:00 PM | M5: PHY | N5: Monday | O5: 7:00 PM - 10:00 PM | P5: ONL | Q5: Saturday | R5: 7:00 PM - 10:00 PM | S5: ONL | T5: OHD | U5: even | V5: شركة AMIT Learning | W5: محافظة القاهرة , مدينة نصر , السراج مول - مدخل رقم 4 - شقه 56 خلفي - الدور الخامس | X5: https://g.co/kgs/6t7v8ie | Y5: even | Z5: graduated | AA5: 24 | AB5: 25 | AD5: 46354
A6: ONL | B6: AMT | C6: AI & data Science | D6: Microsoft Machine Learning Engineer | E6: ONL4_AIS2_G3 | F6: 17 | G6: George Samul | H6: 1022331830 | I6: george.samuel@amit-learning.com | J6: 28405272100158 | K6: Friday | L6: 2:00 PM 5:00 PM | M6: ONL | N6: Saturday | O6: 9:00 AM 12:00 PM | P6: ONL | Q6: Monday | R6: 7:00 PM - 10:00 PM | S6: ONL | T6: OHD | V6: Online | W6: Online | X6: Online | Y6: ONL | Z6: graduated | AA6: 17 | AB6: 30 | AD6: 46361
A7: ONL | B7: AMT | C7: AI & data Science | D7: Generative AI Professional | E7: ONL4_AIS3_G1 | F7: 16 | G7: baraa Wael | H7: 1080431006 | I7: baraa.wael@amit-learning.com | J7: 403797749 | K7: Monday | L7: 7:00 PM - 10:00 PM | M7: ONL | N7: Saturday | O7: 7:00 PM - 10:00 PM | P7: ONL | Q7: Friday | R7: 2:00 PM - 5:00 PM | S7: ONL | T7: Nova | V7: Online | W7: Online | X7: Online | Y7: ONL | Z7: graduated | AA7: 18 | AB7: 30 | AD7: 46361
A8: GIZ | B8: AMT | C8: AI & data Science | D8: Data Scientist | E8: GIZ4_AIS4_G1 | F8: 20 | G8: aya saber | H8: 1116209288 | I8: aya.saber@amit-learning.com | J8: 29805140102781 | K8: Monday | L8: 7:00 PM - 10:00 PM | M8: PHY | N8: Saturday | O8: 7:00 PM - 10:00 PM | P8: ONL | Q8: Friday | R8: 1:00 PM - 4:00 PM | S8: ONL | T8: Nova | U8: Odd | V8: شركة AMIT Learning | W8: محافظة القاهرة ,كورنيش المعادي برج السلام بجوار مستشفى السلام الدولي الدور الثاني أعلى معامل الفا وصيدليه العزبى | X8: https://g.co/kgs/u6bjp9g | Y8: Odd | Z8: graduated | AA8: 21 | AB8: 25 | AD8: 46354
A9: ONL | B9: AMT | C9: Software Development | D9: Software Tester | E9: ONL4_SWD6_S1 | F9: 30 | G9: Mahmoud Helal | I9: mahmoud.helal@amit-learning.com | J9: 29803081402633 | K9: Friday | L9: 5:00 PM - 8:00 PM | M9: ONL | N9: Saturday | O9: 7:00 PM - 10:00 PM | P9: ONL | Q9: Monday | R9: 7:00 PM - 10:00 PM | S9: ONL | T9: Nova | V9: Online | W9: Online | X9: Online | Y9: ONL | Z9: Student | AA9: 27 | AB9: 30 | AD9: 46354
A10: ONL | B10: AMT | C10: Software Development | D10: Software Tester | E10: ONL4_SWD6_G3 | F10: 19 | G10: Mahmoud Helal | H10: 1010340231 | I10: mahmoud.helal@amit-learning.com | J10: 29803081402633 | K10: Friday | L10: 9:00 AM - 12:00PM | M10: ONL | N10: Saturday | O10: 10:00 AM - 1:00 PM | P10: ONL | Q10: Monday | R10: 7:00 PM - 10:00 PM | S10: ONL | T10: Nova | V10: Online | W10: Online | X10: Online | Y10: ONL | Z10: graduated | AA10: 20 | AB10: 30 | AD10: 46354
A11: BNS | B11: AMT | C11: Software Development | D11: React Frontend Web Developer | E11: BNS4_SWD2_S1 | F11: 15 | G11: Ibrahim Eltbakh | H11: 1024556364 | I11: Ibrahim.Eltbakhamit-learning.com | J11: 30008021602219 | K11: Friday | L11: 1:00 PM - 4:00 PM | M11: PHY | N11: Tuesday | O11: 7:00 PM - 10:00 PM | P11: ONL | Q11: Sunday | R11: 7:00 PM - 10:00 PM | S11: ONL | T11: Nova | U11: Odd | V11: ONL | W11: ONL | X11: ONL | Y11: Odd | Z11: Student | AA11: 16 | AB11: 25 | AD11: 46354
A12: BNS | B12: AMT | C12: AI & data Science | D12: Microsoft Machine Learning Engineer | E12: BNS4_AIS2_S1 | F12: 24 | G12: ahmed adel Hekal | H12: 1151277609 | I12: Ahmed.adel.hekal@amit-learning.com | J12: 29403211401172 | K12: Friday | L12: 4:00 PM - 7:00 PM | M12: PHY | N12: Wednesday | O12: 7:00 PM - 10:00 PM | P12: ONL | Q12: Thursday | R12: 7:00 PM - 10:00 PM | S12: ONL | T12: OHD | U12: Odd | V12: ONL | W12: ONL | X12: ONL | Y12: Odd | Z12: Student | AA12: 24 | AB12: 25 | AD12: 46354
A13: CAI | B13: AMT | C13: AI & data Science | D13: Microsoft Data Engineer | E13: CAI4_AIS5_G1 | F13: 22 | G13: Yousef Ahmed | H13: 1155211664 | I13: youssef.ahmed@amit-learning.com | J13: 30012210200374 | K13: Saturday | L13: 4:00 PM - 7:00 PM | M13: PHY | N13: Tuesday | O13: 7:00 PM - 10:00 PM | P13: ONL | Q13: Sunday | R13: 7:00 PM - 10:00 PM | S13: ONL | T13: Nova | U13: even | V13: شركة AMIT Learning | W13: محافظة القاهرة , مدينة نصر , السراج مول - مدخل رقم 4 - شقه 56 خلفي - الدور الخامس | X13: https://g.co/kgs/6t7v8ie | Y13: even | Z13: graduated | AA13: 25 | AB13: 25 | AD13: 46355
A14: BNS | B14: AMT | C14: AI & data Science | D14: Microsoft Data Engineer | E14: BNS4_AIS5_S1 | F14: 24 | G14: ahmed adel Hekal | H14: 1151277609 | I14: Ahmed.adel.hekal@amit-learning.com | J14: 29403211401172 | K14: Friday | L14: 9:00 AM - 12:00 PM | M14: PHY | N14: Saturday | O14: 7:00 PM - 10:00 PM | P14: ONL | Q14: Thursday | R14: 7:00 PM - 10:00 PM | S14: ONL | T14: Nova | U14: Odd | V14: ONL | W14: ONL | X14: ONL | Y14: Odd | Z14: Student | AA14: 25 | AB14: 25 | AD14: 46354
A15: BNS | B15: AMT | C15: AI & data Science | D15: Data Scientist | E15: BNS4_AIS4_S1 | F15: 14 | G15: ahmed adel Hekal | H15: 1151277609 | I15: Ahmed.adel.hekal@amit-learning.com | J15: 29403211401172 | K15: Friday | L15: 1:00 PM - 4:00 PM | M15: PHY | N15: Sunday | O15: 7:00 PM - 10:00 PM | P15: ONL | Q15: Tuesday | R15: 7:00 PM - 10:00 PM | S15: ONL | T15: Nova | U15: Odd | V15: ONL | W15: ONL | X15: ONL | Y15: Odd | Z15: Student | AA15: 14 | AB15: 25 | AD15: 46354
A16: ONL | B16: AMT | C16: Software Development | D16: Software Tester | E16: ONL4_SWD6_G1 | F16: 26 | G16: Mahmoud Helal | H16: 1010340231 | I16: mahmoud.helal@amit-learning.com | J16: 29803081402633 | K16: Monday | L16: 7:00 PM - 10:00 PM | M16: ONL | N16: Wednesday | O16: 7:00 PM - 10:00 PM | P16: ONL | Q16: Friday | R16: 7:00 PM - 10:00 PM | S16: ONL | T16: Nova | V16: Online | W16: Online | X16: Online | Y16: ONL | Z16: graduated | AA16: 25 | AB16: 30 | AD16: 46354
A17: MNF | B17: AMT | C17: Software Development | D17: Software Tester | E17: MNF4_SWD6_S1 | F17: 21 | G17: Ahmed Sayed mohamed | H17: 1091481773 | I17: ahmed.sayed@amit-learning.com | J17: 29911202501216 | K17: Saturday | L17: 10:00 AM - 1:00 PM | M17: PHY | N17: Thursday | O17: 7:00 PM - 10:00 PM | P17: ONL | Q17: Friday | R17: 4:00 PM - 7:00 PM | S17: ONL | T17: Nova | U17: even | V17: كلية الحاسبات و المعلومات جامعة المنوفية | W17: الدور الرابع علوى | X17: https://maps.app.goo.gl/Xxd9ZjGnW4vEsJpb8 | Y17: even | Z17: Student | AA17: 21 | AB17: 25 | AD17: 46354
A18: ONL | B18: AMT | C18: Software Development | D18: React Frontend Web Developer | E18: ONL4_SWD2_G3 | F18: 20 | G18: Ibrahim Eltbakh | H18: 1024556364 | I18: Ibrahim.Eltbakhamit-learning.com | J18: 30008021602219 | K18: Monday | L18: 7:00 PM - 10:00 PM | M18: ONL | N18: Wednesday | O18: 7:00 PM - 10:00 PM | P18: ONL | Q18: Friday | R18: 7:00 PM - 10:00 PM | S18: ONL | T18: Nova | V18: Online | W18: Online | X18: Online | Y18: ONL | Z18: graduated | AA18: 22 | AB18: 30 | AD18: 46354
A19: ONL | B19: AMT | C19: InfraStructure & Security | D19: Cyber Security Incident Response Analyst | E19: ONL4_ISS2_S1 | F19: 32 | G19: Mostafa Abdelmonem | H19: 1555734733 | J19: 29907300000000 | K19: Tuesday | L19: 7:00 PM - 10:00 PM | M19: ONL | N19: Sunday | O19: 7:00 PM - 10:00 PM | P19: ONL | Q19: Friday | R19: 5:00 PM - 8:00 PM | S19: ONL | T19: Nova | V19: Online | W19: Online | X19: Online | Y19: ONL | Z19: Student | AA19: 31 | AB19: 30 | AD19: 46354
A20: ONL | B20: AMT | C20: InfraStructure & Security | D20: Cyber Security Incident Response Analyst | E20: ONL4_ISS2_G1 | F20: 16 | G20: Bishoy Fouad Fahim | H20: 1066993036 | I20: bishoy.fahim@amit-learning.com | J20: 29502020202054 | K20: Friday | L20: 1:00 PM - 4:00 PM | M20: ONL | N20: Tuesday | O20: 7:00 PM - 10:00 PM | P20: ONL | Q20: Sunday | R20: 7:00 PM - 10:00 PM | S20: ONL | T20: Nova | V20: Online | W20: Online | X20: Online | Y20: ONL | Z20: graduated | AA20: 19 | AB20: 30 | AD20: 46354
A21: ONL | B21: AMT | C21: InfraStructure & Security | D21: Cyber Security Incident Response Analyst | E21: ONL4_ISS2_S2 | F21: 33 | G21: Mostafa Abdelmonem | H21: 1555734733 | J21: 29907300000000 | K21: Friday | L21: 9:00 AM - 12:00 PM | M21: ONL | N21: Wednesday | O21: 7:00 PM - 10:00 PM | P21: ONL | Q21: Thursday | R21: 7:00 PM - 10:00 PM | S21: ONL | T21: Nova | V21: Online | W21: Online | X21: Online | Y21: ONL | Z21: Student | AA21: 33 | AB21: 30 | AD21: 46354
A22: ONL | B22: AMT | C22: AI & data Science | D22: Microsoft Machine Learning Engineer | E22: ONL4_AIS2_S2 | F22: 30 | G22: George Samul | H22: 1022331830 | I22: george.samuel@amit-learning.com | J22: 28405272100158 | K22: Wednesday | L22: 7:00 PM - 10:00 PM | M22: ONL | N22: Tuesday | O22: 7:00 PM - 10:00 PM | P22: ONL | Q22: Saturday | R22: 7:00 PM - 10:00 PM | S22: ONL | T22: OHD | V22: Online | W22: Online | X22: Online | Y22: ONL | Z22: Student | AA22: 30 | AB22: 30 | AD22: 46355
A23: CAI | B23: AMT | C23: AI & data Science | D23: Microsoft Machine Learning Engineer | E23: CAI4_AIS2_S1 | F23: 25 | G23: Omnia Ahmed | H23: 1155211664 | I23: Omnia.Ahmed@amit-learning.com | J23: 29507041400168 | K23: Friday | L23: 7:00 PM - 10:00 PM | M23: PHY | N23: Wednesday | O23: 7:00 PM - 10:00 PM | P23: ONL | Q23: Thursday | R23: 7:00 PM - 10:00 PM | S23: ONL | T23: OHD | U23: even | V23: شركة AMIT Learning | W23: محافظة القاهرة , مدينة نصر , السراج مول - مدخل رقم 4 - شقه 56 خلفي - الدور الخامس | X23: https://g.co/kgs/6t7v8ie | Y23: even | Z23: Student | AA23: 25 | AB23: 25 | AD23: 46354
A24: CAI | B24: AMT | C24: AI & data Science | D24: Microsoft Machine Learning Engineer | E24: CAI4_AIS2_G1 | F24: 25 | G24: Omnia Ahmed | H24: 1155211664 | I24: Omnia.Ahmed@amit-learning.com | J24: 29507041400168 | K24: Friday | L24: 1:00 PM - 4:00 PM | M24: PHY | N24: Saturday | O24: 7:00 PM - 10:00 PM | P24: ONL | Q24: Monday | R24: 7:00 PM - 10:00 PM | S24: ONL | T24: OHD | U24: even | V24: شركة AMIT Learning | W24: محافظة القاهرة , مدينة نصر , السراج مول - مدخل رقم 4 - شقه 56 خلفي - الدور الخامس | X24: https://g.co/kgs/6t7v8ie | Y24: even | Z24: graduated | AA24: 25 | AB24: 25 | AD24: 46354
A25: GIZ | B25: AMT | C25: AI & data Science | D25: Microsoft Machine Learning Engineer | E25: GIZ4_AIS2_S2 | F25: 24 | G25: baraa Wael | H25: 1080431006 | I25: baraa.wael@amit-learning.com | J25: 403797749 | K25: Saturday | L25: 9:00 AM - 12:00 PM | M25: PHY | N25: Thursday | O25: 7:00 PM - 10:00 PM | P25: ONL | Q25: Friday | R25: 4:00 PM - 7:00 PM | S25: ONL | T25: OHD | U25: Odd | V25: شركة AMIT Learning | W25: محافظة القاهرة ,كورنيش المعادي برج السلام بجوار مستشفى السلام الدولي الدور الثاني أعلى معامل الفا وصيدليه العزبى | X25: https://g.co/kgs/u6bjp9g | Y25: Odd | Z25: Student | AA25: 24 | AB25: 25 | AD25: 46354
A26: GIZ | B26: AMT | C26: AI & data Science | D26: Microsoft Machine Learning Engineer | E26: GIZ4_AIS2_S1 | F26: 25 | G26: George Samul | H26: 1022331830 | I26: george.samuel@amit-learning.com | J26: 28405272100158 | K26: Friday | L26: 7:00:00 PM - 10:00 PM | M26: PHY | N26: Sunday | O26: 7:00 PM - 10:00 PM | P26: ONL | Q26: Tuesday | R26: 7:00 PM - 10:00 PM | S26: ONL | T26: OHD | U26: Odd | V26: شركة AMIT Learning | W26: محافظة القاهرة ,كورنيش المعادي برج السلام بجوار مستشفى السلام الدولي الدور الثاني أعلى معامل الفا وصيدليه العزبى | X26: https://g.co/kgs/u6bjp9g | Y26: Odd | Z26: Student | AA26: 25 | AB26: 25 | AD26: 46354
A27: CAI | B27: AMT | C27: AI & data Science | D27: Generative AI Professional | E27: CAI4_AIS3_S1 | F27: 18 | G27: ahmed adel Hekal | H27: 1151277609 | I27: Ahmed.adel.hekal@amit-learning.com | J27: 29403211401172 | K27: Monday | L27: 7:00 PM - 10:00 PM | M27: PHY | N27: Saturday | O27: 9:00 AM - 12:00 PM | P27: ONL | Q27: Friday | R27: 7:00 PM - 10:00 PM | S27: ONL | T27: Nova | U27: even | V27: شركة AMIT Learning | W27: محافظة القاهرة , مدينة نصر , السراج مول - مدخل رقم 4 - شقه 56 خلفي - الدور الخامس | X27: https://g.co/kgs/6t7v8ie | Y27: even | Z27: Student | AA27: 22 | AB27: 25 | AD27: 46354
A28: CAI | B28: AMT | C28: AI & data Science | D28: Generative AI Professional | E28: CAI4_AIS3_G1 | F28: 17 | G28: baraa Wael | H28: 1080431006 | I28: baraa.wael@amit-learning.com | J28: 403797749 | K28: Saturday | L28: 1:00 PM - 4:00 PM | M28: PHY | N28: Tuesday | O28: 7:00 PM - 10:00 PM | P28: ONL | Q28: Sunday | R28: 7:00 PM - 10:00 PM | S28: ONL | T28: Nova | U28: even | V28: شركة AMIT Learning | W28: محافظة القاهرة , مدينة نصر , السراج مول - مدخل رقم 4 - شقه 56 خلفي - الدور الخامس | X28: https://g.co/kgs/6t7v8ie | Y28: even | Z28: graduated | AA28: 23 | AB28: 25 | AD28: 46355
A29: GIZ | B29: AMT | C29: AI & data Science | D29: Generative AI Professional | E29: GIZ4_AIS3_G1 | F29: 16 | G29: baraa Wael | H29: 1080431006 | I29: baraa.wael@amit-learning.com | J29: 403797749 | K29: Friday | L29: 1:00 PM - 4:00 PM | M29: PHY | N29: Sunday | O29: 7:00 PM - 10:00 PM | P29: ONL | Q29: Tuesday | R29: 7:00 PM - 10:00 PM | S29: ONL | T29: Nova | U29: Odd | V29: شركة AMIT Learning | W29: محافظة القاهرة ,كورنيش المعادي برج السلام بجوار مستشفى السلام الدولي الدور الثاني أعلى معامل الفا وصيدليه العزبى | X29: https://g.co/kgs/u6bjp9g | Y29: Odd | Z29: graduated | AA29: 20 | AB29: 25 | AD29: 46354
A30: GIZ | B30: AMT | C30: AI & data Science | D30: Generative AI Professional | E30: GIZ4_AIS3_S1 | F30: 18 | G30: baraa Wael | H30: 1080431006 | I30: baraa.wael@amit-learning.com | J30: 403797749 | K30: Friday | L30: 9:00 AM - 12:00 PM | M30: PHY | N30: Wednesday | O30: 7:00 PM - 10:00 PM | P30: ONL | Q30: Thursday | R30: 7:00 PM - 10:00 PM | S30: ONL | T30: Nova | U30: Odd | V30: شركة AMIT Learning | W30: محافظة القاهرة ,كورنيش المعادي برج السلام بجوار مستشفى السلام الدولي الدور الثاني أعلى معامل الفا وصيدليه العزبى | X30: https://g.co/kgs/u6bjp9g | Y30: Odd | Z30: Student | AA30: 20 | AB30: 25 | AD30: 46354
A31: ONL | B31: AMT | C31: AI & data Science | D31: Generative AI Professional | E31: ONL4_AIS3_S3 | F31: 29 | G31: Mohamed Gomaa | H31: 1143300459 | I31: Mohamed.Gomaa@amit-learning.com | J31: 29310141201237 | K31: Thursday | L31: 7:00 PM - 10:00 PM | M31: ONL | N31: Wednesday | O31: 7:00 PM - 10:00 PM | P31: ONL | Q31: Friday | R31: 9:00 AM - 12:00PM | S31: ONL | T31: Nova | V31: Online | W31: Online | X31: Online | Y31: ONL | Z31: Student | AA31: 30 | AB31: 30 | AD31: 46354
A32: ONL | B32: AMT | C32: AI & data Science | D32: Generative AI Professional | E32: ONL4_AIS3_S2 | F32: 29 | G32: Mohamed Gomaa | H32: 1143300459 | I32: Mohamed.Gomaa@amit-learning.com | J32: 29310141201237 | K32: Friday | L32: 9:00 AM - 12:00PM | M32: ONL | N32: Tuesday | O32: 7:00 PM - 10:00 PM | P32: ONL | Q32: Sunday | R32: 7:00 PM - 10:00 PM | S32: ONL | T32: Nova | V32: Online | W32: Online | X32: Online | Y32: ONL | Z32: Student | AA32: 30 | AB32: 30 | AD32: 46354
A33: ONL | B33: AMT | C33: AI & data Science | D33: Microsoft Data Engineer | E33: ONL4_AIS5_G1 | F33: 29 | G33: George Samul | H33: 1022331830 | I33: george.samuel@amit-learning.com | J33: 28405272100158 | K33: Friday | L33: 9:00 AM 12:00 PM | M33: ONL | N33: Saturday | O33: 2:00 PM - 5:00 PM | P33: ONL | Q33: Monday | R33: 7:00 PM - 10:00 PM | S33: ONL | T33: Nova | V33: Online | W33: Online | X33: Online | Y33: ONL | Z33: graduated | AA33: 30 | AB33: 30 | AD33: 46354
A34: ONL | B34: AMT | C34: AI & data Science | D34: Microsoft Data Engineer | E34: ONL4_AIS5_S3 | F34: 30 | G34: Yousef Ahmed | H34: 1155211664 | I34: youssef.ahmed@amit-learning.com | J34: 30012210200374 | K34: Monday | L34: 7:00 PM - 10:00 PM | M34: ONL | N34: Wednesday | O34: 7:00 PM - 10:00 PM | P34: ONL | Q34: Friday | R34: 7:00 PM - 10:00 PM | S34: ONL | T34: Nova | V34: Online | W34: Online | X34: Online | Y34: ONL | Z34: Student | AA34: 35 | AB34: 30 | AD34: 46354
A35: ONL | B35: AMT | C35: AI & data Science | D35: Data Scientist | E35: ONL4_AIS4_S4 | F35: 30 | G35: ahmed adel Hekal | H35: 1151277609 | I35: Ahmed.adel.hekal@amit-learning.com | J35: 29403211401172 | K35: Friday | L35: 7:00 PM - 10:00 PM | M35: ONL | N35: Tuesday | O35: 7:00 PM - 10:00 PM | P35: ONL | Q35: Sunday | R35: 7:00 PM - 10:00 PM | S35: ONL | T35: Nova | V35: Online | W35: Online | X35: Online | Y35: ONL | Z35: Student | AA35: 30 | AB35: 30 | AD35: 46354
A36: ONL | B36: AMT | C36: AI & data Science | D36: Data Scientist | E36: ONL4_AIS4_S2 | F36: 23 | G36: Mohamed Gomaa | H36: 1143300459 | I36: Mohamed.Gomaa@amit-learning.com | J36: 29310141201237 | K36: Saturday | L36: 10:00 AM - 1:00PM | M36: ONL | N36: Sunday | O36: 7:00 PM - 10:00 PM | P36: ONL | Q36: Tuesday | R36: 7:00 PM - 10:00 PM | S36: ONL | T36: Nova | V36: Online | W36: Online | X36: Online | Y36: ONL | Z36: Student | AA36: 24 | AB36: 30 | AD36: 46355
A37: GIZ | B37: AMT | C37: AI & data Science | D37: Data Scientist | E37: GIZ4_AIS4_S1 | F37: 15 | G37: George Samul | H37: 1022331830 | I37: george.samuel@amit-learning.com | J37: 28405272100158 | K37: Saturday | L37: 7:00 PM -10:00 PM | M37: PHY | N37: Thursday | O37: 7:00 PM -10:00 PM | P37: ONL | Q37: Wednesday | R37: 7:00 PM - 10:00 PM | S37: ONL | T37: Nova | U37: Odd | V37: شركة AMIT Learning | W37: محافظة القاهرة ,كورنيش المعادي برج السلام بجوار مستشفى السلام الدولي الدور الثاني أعلى معامل الفا وصيدليه العزبى | X37: https://g.co/kgs/u6bjp9g | Y37: Odd | Z37: Student | AA37: 15 | AB37: 25 | AD37: 46355
A38: CAI | B38: AMT | C38: AI & data Science | D38: Data Scientist | E38: CAI4_AIS4_S1 | F38: 23 | G38: ali hendi | H38: 1011130719 | I38: ali.hendi@amit-learning.com | J38: 29407201201391 | K38: Monday | L38: 7:00 PM - 10:00 PM | M38: PHY | N38: Friday | O38: 7:00 PM - 10:00 PM | P38: ONL | Q38: Saturday | R38: 7:00 PM - 10:00 PM | S38: ONL | T38: Nova | U38: Odd | V38: شركة AMIT Learning | W38: محافظة القاهرة , مدينة نصر , السراج مول - مدخل رقم 4 - شقه 56 خلفي - الدور الخامس | X38: https://g.co/kgs/6t7v8ie | Y38: Odd | Z38: Student | AA38: 24 | AB38: 25 | AD38: 46354
A39: CAI | B39: AMT | C39: AI & data Science | D39: Data Scientist | E39: CAI4_AIS4_G2 | F39: 18 | G39: Omnia Ahmed | H39: 1155211664 | I39: Omnia.Ahmed@amit-learning.com | J39: 29507041400168 | K39: Tuesday | L39: 7:00 PM - 10:00 PM | M39: PHY | N39: Saturday | O39: 7:00 PM - 10:00 PM | P39: ONL | Q39: Friday | R39: 1:00PM - 4:00 PM | S39: ONL | T39: OHD | U39: even | V39: شركة AMIT Learning | W39: محافظة القاهرة , مدينة نصر , السراج مول - مدخل رقم 4 - شقه 56 خلفي - الدور الخامس | X39: https://g.co/kgs/6t7v8ie | Y39: even | Z39: graduated | AA39: 19 | AB39: 25 | AD39: 46354
A40: GIZ | B40: AMT | C40: Software Development | D40: Software Tester | E40: GIZ4_SWD6_S2 | F40: 20 | G40: Ziad Amr | H40: 1272057783 | I40: ziad.amr@amit-learning.com | J40: 30201230101156 | K40: Saturday | L40: 4:00 PM - 7:00 PM | M40: PHY | N40: Friday | O40: 4:00 PM - 7:00 PM | P40: ONL | Q40: Wednesday | R40: 7:00 PM - 10:00 PM | S40: ONL | T40: Nova | U40: even | V40: شركة AMIT Learning | W40: محافظة القاهرة ,كورنيش المعادي برج السلام بجوار مستشفى السلام الدولي الدور الثاني أعلى معامل الفا وصيدليه العزبى | X40: https://g.co/kgs/u6bjp9g | Y40: even | Z40: Student | AA40: 22 | AB40: 25 | AD40: 46354
...
